Workbook
Name beed: Table1[[#All],[Unit Number]:[NO. OF BEDROOMS]]
Name Slicer_AREA_CATEGORY: #N/A
Name Slicer_AREA_CATEGORY1: #N/A
Name Slicer_AREA_CATEGORY11: #N/A
Name Slicer_AREA_CATEGORY111: #N/A
Name Slicer_AREA_CATEGORY1111: #N/A
Name Slicer_AREA_CATEGORY11111: #N/A
Name Slicer_AREA_CATEGORY111111: #N/A
Name Slicer_AREA_CATEGORY1111111: #N/A
Name Slicer_AREA_CATEGORY11111111: #N/A
Name Slicer_AREA_CATEGORY111111111: #N/A
Name Slicer_AREA_CATEGORY1111111111: #N/A
Name Slicer_AREA_CATEGORY11111111111: #N/A
Name Slicer_AREA_CATEGORY111111111111: #N/A
Name Slicer_BLD._TYPE: #N/A
Name Slicer_BLD._TYPE1: #N/A
Name Slicer_BLD._TYPE11: #N/A
Name Slicer_BLD_No.: #N/A
Name Slicer_BLD_No.1: #N/A
Name Slicer_BLD_No.11: #N/A
Name Slicer_CONSTRUCTION_PHASE: #N/A
Name Slicer_CONSTRUCTION_PHASE1: #N/A
Name Slicer_CONSTRUCTION_PHASE11: #N/A
Name Slicer_PREMIUM_CATEGORY: #N/A
Name Slicer_PREMIUM_CATEGORY1: #N/A
Name Slicer_PREMIUM_CATEGORY11: #N/A
Name Slicer_PREMIUM_CATEGORY2: #N/A
Name Slicer_PREMIUM_CATEGORY21: #N/A
Name Slicer_PREMIUM_CATEGORY211: #N/A
Name Slicer_PREMIUM_CATEGORY2111: #N/A
Name Slicer_PREMIUM_CATEGORY21111: #N/A
Name Slicer_PREMIUM_CATEGORY211111: #N/A
Name Slicer_PREMIUM_CATEGORY2111111: #N/A
Name Slicer_PREMIUM_CATEGORY21111111: #N/A
Name Slicer_PREMIUM_CATEGORY211111111: #N/A
Name Slicer_PREMIUM_CATEGORY2111111111: #N/A
Name Slicer_PREMIUM_CATEGORY21111111111: #N/A
Name Slicer_PREMIUM_CATEGORY211111111111: #N/A
Name Slicer_PREMIUM_CATEGORY2111111111111: #N/A
Name Slicer_SELLING_PHASE_NAME: #N/A
Name Slicer_SELLING_PHASE_NAME1: #N/A
Name Slicer_SELLING_PHASE_NAME11: #N/A
Name Slicer_SELLING_PHASE_NAME111: #N/A
Name Slicer_SELLING_PHASE_NAME1111: #N/A
Name Slicer_SELLING_PHASE_NAME11111: #N/A
Name Slicer_SELLING_PHASE_NAME111111: #N/A
Name Slicer_SELLING_PHASE_NAME1111111: #N/A
Name Slicer_SELLING_PHASE_NAME11111111: #N/A
Name Slicer_SELLING_PHASE_NAME111111111: #N/A
Name Slicer_SELLING_PHASE_NAME1111111111: #N/A
Name Slicer_SELLING_PHASE_NAME11111111111: #N/A
Name Slicer_SELLING_PHASE_NAME111111111111: #N/A

Sheet PHASES PREM RANGE
A1: Phases | B1: Min of UNIT (BUILDING) RATE (SEMI FINISHED) | C1: Max of UNIT (BUILDING) RATE (SEMI FINISHED) | D1: Average of UNIT (BUILDING) RATE (SEMI FINISHED) | E1: Min of UNIT (BUILDING) RATE (BASIC FINISH)2 | F1: Max of UNIT (BUILDING) RATE (BASIC FINISH) | G1: Average of UNIT (BUILDING) RATE (BASIC FINISH) | H1: Min of UNIT (BUILDING) RATE (FULLY FINISH) | I1: Max of UNIT (BUILDING) RATE (FULLY FINISH) | J1: Average of UNIT (BUILDING) RATE (FULLY FINISH)
A2: R 1 | B2: 43875 | C2: 46225 | D2: 45023.316 | E2: 48375 | F2: 50725 | G2: 49523.316 | H2: 51375 | I2: 53725 | J2: 52523.316
A3: R 2 | B3: 45407.5 | C3: 47457.5 | D3: 46356.091 | E3: 49907.5 | F3: 51957.5 | G3: 50856.091 | H3: 52907.5 | I3: 54957.5 | J3: 53856.091
A4: R 3 | B4: 46331.25 | C4: 48667.5 | D4: 47460.508 | E4: 50831.25 | F4: 53167.5 | G4: 51960.508 | H4: 53831.25 | I4: 56167.5 | J4: 54960.508
A5: R 4 | B5: 47541.875 | C5: 49906.875 | D5: 48749.631 | E5: 52041.875 | F5: 54406.875 | G5: 53249.631 | H5: 55041.875 | I5: 57406.875 | J5: 56249.631
A6: R 5 | B6: 48922.5 | C6: 51122.5 | D6: 49988.689 | E6: 53422.5 | F6: 55622.5 | G6: 54488.689 | H6: 56422.5 | I6: 58622.5 | J6: 57488.689
A7: R 6 | B7: 50758.5 | C7: 53038.5 | D7: 51816.325 | E7: 55258.5 | F7: 57538.5 | G7: 56316.325 | H7: 58258.5 | I7: 60538.5 | J7: 59316.325
A8: R 7 | B8: 52392 | C8: 55047 | D8: 53655.315 | E8: 56892 | F8: 59547 | G8: 58155.315 | H8: 59892 | I8: 62547 | J8: 61155.315
A9: R 8 | B9: 54442.5 | C9: 57096 | D9: 55649.898 | E9: 58942.5 | F9: 61596 | G9: 60149.898 | H9: 61942.5 | I9: 64596 | J9: 63149.898
A10: R 9 | B10: 56322 | C10: 59062.5 | D10: 57551.386 | E10: 60822 | F10: 63562.5 | G10: 62051.386 | H10: 63822 | I10: 66562.5 | J10: 65051.386
A11: R 10 | B11: 59070 | C11: 61974 | D11: 60372.125 | E11: 63570 | F11: 66474 | G11: 64872.125 | H11: 66570 | I11: 69474 | J11: 67872.125
A12: R 11 | B12: 61858.5 | C12: 64860 | D12: 63195.786 | E12: 66358.5 | F12: 69360 | G12: 67695.786 | H12: 69358.5 | I12: 72360 | J12: 70695.786
A13: R 12 | B13: 64670 | C13: 68621.25 | D13: 66504.351 | E13: 69170 | F13: 73121.25 | G13: 71004.351 | H13: 72170 | I13: 76121.25 | J13: 74004.351
... A15: Grand Total | B15: 43875 | C15: 80815 | D15: 54113.272 | E15: 48375 | F15: 85315 | G15: 58613.272 | H15: 51375 | I15: 88315 | J15: 61613.272

Sheet DASHBOARD (7)
A1: Row Labels | B1: Count of Unit Selling Area | C1: Count of Unit Selling Area2
A2: 1 BEDROOM (STUDIO) | B2: 68 | C2: 0.079254079
A3: 2 BEDROOM | B3: 176 | C3: 0.20512821
A4: 3 BEDROOM | B4: 526 | C4: 0.61305361
A5: 3 BEDROOM + LIVING | B5: 70 | C5: 0.081585082
A6: 3 BEDROOM + LIVING (DUPLEX) | B6: 18 | C6: 0.020979021
A7: Grand Total | B7: 858 | C7: 1

Sheet product mix dash
A1: Unit Area | B1: Count of Unit Selling Area
A2: 63 | B2: 16
A3: 84 | B3: 12
A4: 106 | B4: 12
A5: 108 | B5: 20
A6: 110 | B6: 26
A7: 112 | B7: 12
A8: 116 | B8: 19
A9: 117 | B9: 19
A10: 119 | B10: 15
A11: 121 | B11: 12
A12: 153 | B12: 24
A13: 155 | B13: 88
... A26: 228 | B26: 24
A27: Grand Total | B27: 694

Sheet premium cat. per phase dash
A1: SELLING PHASE NAME | B1: R 1 | D1: SELLING PHASE NAME | E1: R 7
A3: Premium Category | B3: Count of Unit Selling Area | D3: Premium Category | E3: Count of Unit Selling Area
A4: A | B4: 33 | D4: A | E4: 16
A5: B | B5: 49 | D5: B | E5: 20
A6: C | B6: 62 | D6: C | E6: 30
A7: Grand Total | B7: 144 | D7: Grand Total | E7: 66
A9: SELLING PHASE NAME | B9: R 2 | D9: SELLING PHASE NAME | E9: R 8
A11: Premium Category | B11: Count of Unit Selling Area | D11: Premium Category | E11: Count of Unit Selling Area
A12: A | B12: 14 | D12: A | E12: 25
A13: B | B13: 19 | D13: B | E13: 27
A14: C | B14: 22 | D14: C | E14: 39
A15: Grand Total | B15: 55 | D15: Grand Total | E15: 91
A16: SELLING PHASE NAME | B16: R 3
D17: SELLING PHASE NAME | E17: R 9
A18: Premium Category | B18: Count of Unit Selling Area
A19: A | B19: 16 | D19: Premium Category | E19: Count of Unit Selling Area
A20: B | B20: 16 | D20: A | E20: 17
A21: C | B21: 30 | D21: B | E21: 20
A22: Grand Total | B22: 62 | D22: C | E22: 27
D23: Grand Total | E23: 64
A24: SELLING PHASE NAME | B24: R 4
D25: SELLING PHASE NAME | E25: R 10
A26: Premium Category | B26: Count of Unit Selling Area
A27: A | B27: 21 | D27: Premium Category | E27: Count of Unit Selling Area
A28: B | B28: 30 | D28: A | E28: 6
A29: C | B29: 37 | D29: B | E29: 8
A30: Grand Total | B30: 88 | D30: C | E30: 10
D31: Grand Total | E31: 24
A32: SELLING PHASE NAME | B32: R 5
D33: SELLING PHASE NAME | E33: R 11
A34: Premium Category | B34: Count of Unit Selling Area
A35: A | B35: 17 | D35: Premium Category | E35: Count of Unit Selling Area
A36: B | B36: 19 | D36: A | E36: 6
A37: C | B37: 25 | D37: B | E37: 6
A38: Grand Total | B38: 61 | D38: C | E38: 9
D39: Grand Total | E39: 21
A40: SELLING PHASE NAME | B40: R 6
D41: SELLING PHASE NAME | E41: R 12
A42: Premium Category | B42: Count of Unit Selling Area
A43: A | B43: 13 | D43: Premium Category | E43: Count of Unit Selling Area
...

Sheet PV calculation
F5: UNIT PRICING PAYMENT
F6: DP % | G6: 0.05 | H6: 0.1 | P6: =P9/J7 -> 0.88888889
G7: Unit (2) | H7: Unit (2) | J7: =90/H16 -> 3.2142857 | K7: =12*J7 -> 38.571429 | M7: =50/16 -> 3.125 | P7: =P6*210000 -> 186666.67
F8: Unit area | G8: 155 | H8: 155 | J8: 2.5 | K8: =J8*12 -> 30
F9: Unit price/m2 | G9: 41530 | H9: 41530 | K9: 10 | N9: =2.5*28 -> 70 | P9: =80/28 -> 2.8571429
F10: Total Unit Price | G10: =G9*G8 -> 6437150 | H10: =H9*H8 -> 6437150 | K10: 10
F11: DP Value | G11: =G10*G6 -> 321857.5 | H11: =H10*H6 -> 643715
F12: No. of installments years | G12: 6 | H12: 7
F13: Installment value | G13: =(G10-G11)/(G12*G15) -> 254803.85 | H13: =(H10-H11)/(H12*H15) -> 206908.39
D14: =G13*G16 -> 6115292.5 | F14: Intrest Rate (yearly) | G14: 0.13 | H14: 0.13
F15: No. of Periods | G15: 4 | H15: 4
F16: Total no. of Periods | G16: =G12*G15 -> 24 | H16: =H12*H15 -> 28
F17: Intrest Rate (Period) | G17: =G14/G15 -> 0.0325 | H17: =H14/H15 -> 0.0325
F18: Present Value (PV) | G18: =(((1-(1+G17)^(-G16))/(G17))*(G13))+(G11) -> 4523151 | H18: =(((1-(1+H17)^(-H16))/(H17))*(H13))+(H11) -> 4410128.8
F19: Discount Rate (%) | G19: =1-(G18/G10) -> 0.2973364 | H19: =1-(H18/H10) -> 0.3148942
F20: Present Value (PV)/M2 | G20: =G18/G8 -> 29181.619 | H20: =H18/H8 -> 28452.444
F22: FINISHING PAYMENT (FULLY)
F23: DP % | G23: 0.1 | H23: 0.05
G24: Unit (1) | H24: Unit (1)
F25: Unit area | G25: 155 | H25: 155
F26: Unit price | G26: 7500 | H26: 7500
F27: Total Unit Price | G27: =G26*G25 -> 1162500 | H27: =H26*H25 -> 1162500
F28: DP Value | G28: =G27*G23 -> 116250 | H28: =H27*H23 -> 58125
F29: No. of installments years | G29: 7 | H29: 6
F30: Installment value | G30: =(G27-G28)/(G29*G32) -> 37366.071 | H30: =(H27-H28)/(H29*H32) -> 46015.625
F31: Intrest Rate (yearly) | G31: 0.13 | H31: 0.13
F32: No. of Periods | G32: 4 | H32: 4
F33: Total no. of Periods | G33: =G29*G32 -> 28 | H33: =H29*H32 -> 24
F34: Intrest Rate (Period) | G34: =G31/G32 -> 0.0325 | H34: =H31/H32 -> 0.0325
F35: Present Value (PV) | G35: =(((1-(1+G34)^(-G33))/(G34))*(G30))+(G28) -> 796435.5 | H35: =(((1-(1+H34)^(-H33))/(H34))*(H30))+(H28) -> 816846.43
F36: Present Value (PV)/M2 | G36: =(G35+G28)/G25 -> 5888.2935 | H36: =(H35+H28)/H25 -> 5644.977
F39: FINISHING PAYMENT (BASIC)
F40: DP % | G40: 0.1 | H40: 0.05
G41: Unit (1) | H41: Unit (1)
F42: Unit area | G42: 155 | H42: 155
F43: Unit price | G43: 4500 | H43: 4500
F44: Total Unit Price | G44: =G43*G42 -> 697500 | H44: =H43*H42 -> 697500
F45: DP Value | G45: =G44*G40 -> 69750 | H45: =H44*H40 -> 34875
F46: No. of installments years | G46: 7 | H46: 6
F47: Installment value | G47: =(G44-G45)/(G46*G49) -> 22419.643 | H47: =(H44-H45)/(H46*H49) -> 27609.375
...

Sheet FINISH
B2: FULLY | G2: BASIC
B4: ITEM | C4: QUANTITY | D4: PRICE | E4: TOTAL | G4: ITEM | H4: QUANTITY | I4: PRICE | J4: TOTAL
B5: WALLS | G5: WALLS
B6: PAINT | C6: 650 | D6: 200 | E6: =D6*C6 -> 130000 | G6: PAINT | H6: 650 | I6: 100 | J6: =I6*H6 -> 65000
B7: FUTEC | C7: 90 | D7: 60 | E7: =D7*C7 -> 5400 | G7: FUTEC | H7: 0 | I7: 60 | J7: =I7*H7 -> 0
B8: PORCELAIN WALLS | C8: 135 | D8: 650 | E8: =D8*C8 -> 87750 | G8: PORCELAIN WALLS | H8: 135 | I8: 650 | J8: =I8*H8 -> 87750
B9: ITEM | C9: QUANTITY | D9: PRICE | E9: TOTAL | G9: ITEM | H9: QUANTITY | I9: PRICE | J9: TOTAL
B10: CEILLING | E10: =D10*C10 -> 0 | G10: CEILLING | J10: =I10*H10 -> 0
B11: GYPSUM | C11: 65 | D11: 336 | E11: =D11*C11 -> 21840 | G11: GYPSUM | H11: 0 | I11: 336 | J11: =I11*H11 -> 0
B12: GYPSUM COVE AND CURTIN | C12: 45 | D12: 230 | E12: =D12*C12 -> 10350 | G12: GYPSUM COVE AND CURTIN | H12: 0 | I12: 230 | J12: =I12*H12 -> 0
B13: FUTEC | C13: 40 | D13: 120 | E13: =D13*C13 -> 4800 | G13: FUTEC | H13: 0 | I13: 120 | J13: =I13*H13 -> 0
B14: ITEM | C14: QUANTITY | D14: PRICE | E14: TOTAL | G14: ITEM | H14: QUANTITY | I14: PRICE | J14: TOTAL
B15: FLOORS | E15: =D15*C15 -> 0 | G15: FLOORS | J15: =I15*H15 -> 0
B16: PORCELAIN 01 | C16: 40 | D16: 650 | E16: =D16*C16 -> 26000 | G16: PORCELAIN 01 | H16: 40 | I16: 650 | J16: =I16*H16 -> 26000
B17: PORCELAIN 02 | C17: 85 | D17: 800 | E17: =D17*C17 -> 68000 | G17: PORCELAIN 02 | H17: 85 | I17: 800 | J17: =I17*H17 -> 68000
B18: CERAMIC UNDER HDF | C18: 74 | D18: 200 | E18: =D18*C18 -> 14800 | G18: CERAMIC UNDER HDF | H18: 74 | I18: 200 | J18: =I18*H18 -> 14800
B19: HDF, SKIRT ,ACC. | C19: 74 | D19: 700 | E19: =D19*C19 -> 51800 | G19: HDF, SKIRT ,ACC. | H19: 0 | I19: 700 | J19: =I19*H19 -> 0
B20: MARBLE FLOOR FOR SHOWERS | C20: 7 | D20: 5000 | E20: =D20*C20 -> 35000 | G20: MARBLE FLOOR FOR SHOWERS | H20: 7 | I20: 5000 | J20: =I20*H20 -> 35000
B21: MARBLE THRESHOLDS | C21: 16 | D21: 500 | E21: =D21*C21 -> 8000 | G21: MARBLE THRESHOLDS | H21: 16 | I21: 500 | J21: =I21*H21 -> 8000
B22: ITEM | C22: QUANTITY | D22: PRICE | E22: TOTAL | G22: ITEM | H22: QUANTITY | I22: PRICE | J22: TOTAL
B23: BASIN WORKS | E23: =D23*C23 -> 0 | G23: BASIN WORKS | J23: =I23*H23 -> 0
B24: CHASIS (MARBLE +STEEL) | C24: 3 | D24: 5000 | E24: =D24*C24 -> 15000 | G24: CHASIS (MARBLE +STEEL) | H24: 0 | I24: 5000 | J24: =I24*H24 -> 0
B25: BASIN VANITIES | C25: 3 | D25: 6500 | E25: =D25*C25 -> 19500 | G25: BASIN VANITIES | H25: 0 | I25: 6500 | J25: =I25*H25 -> 0
B26: ITEM | C26: QUANTITY | D26: PRICE | E26: TOTAL | G26: ITEM | H26: QUANTITY | I26: PRICE | J26: TOTAL
B27: WOODEN DOORS | E27: =D27*C27 -> 0 | G27: WOODEN DOORS | J27: =I27*H27 -> 0
B28: WOODEN DOORS WITH ACC. | C28: 10 | D28: 15000 | E28: =D28*C28 -> 150000 | G28: WOODEN DOORS WITH ACC. | H28: 10 | I28: 4000 | J28: =I28*H28 -> 40000
B29: MAIN DOOR WITH ACC. | C29: 1 | D29: 30000 | E29: =D29*C29 -> 30000 | G29: MAIN DOOR WITH ACC. | H29: 1 | I29: 30000 | J29: =I29*H29 -> 30000
B30: ITEM | C30: QUANTITY | D30: PRICE | E30: TOTAL | G30: ITEM | H30: QUANTITY | I30: PRICE | J30: TOTAL
B31: MIRRORS AND GLASS PARTIONS | E31: =D31*C31 -> 0 | G31: MIRRORS AND GLASS PARTIONS | J31: =I31*H31 -> 0
B32: MIRRORS | C32: 3 | D32: 2000 | E32: =D32*C32 -> 6000 | G32: MIRRORS | H32: 0 | I32: 2000 | J32: =I32*H32 -> 0
B33: SECORITE | C33: 3 | D33: 3000 | E33: =D33*C33 -> 9000 | G33: SECORITE | H33: 3 | I33: 3000 | J33: =I33*H33 -> 9000
B34: ITEM | C34: QUANTITY | D34: PRICE | E34: TOTAL | G34: ITEM | H34: QUANTITY | I34: PRICE | J34: TOTAL
B35: ELEC WORKS AND LIGHTING FIX. | E35: =D35*C35 -> 0 | G35: ELEC WORKS AND LIGHTING FIX. | J35: =I35*H35 -> 0
B36: ELEC WORKS AND LIGHTING FIX. | C36: 1 | D36: 250000 | E36: =D36*C36 -> 250000 | G36: ELEC WORKS AND LIGHTING FIX. | H36: 1 | I36: 200000 | J36: =I36*H36 -> 200000
B37: ITEM | C37: QUANTITY | D37: PRICE | E37: TOTAL | G37: ITEM | H37: QUANTITY | I37: PRICE | J37: TOTAL
B38: AC (CHASIS, CONTROL CABLE, COPPER AND PLUM.) | E38: =D38*C38 -> 0 | G38: AC (CHASIS, CONTROL CABLE, COPPER AND PLUM.) | J38: =I38*H38 -> 0
B39: 1.5 | C39: 3 | D39: =(15*(500+150+250))+1750 -> 15250 | E39: =D39*C39 -> 45750 | G39: 1.5 | H39: 3 | I39: =(15*(500+150+250))+1750 -> 15250 | J39: =I39*H39 -> 45750
B40: 3 | C40: 2 | D40: =(15*(600+150+250))+2000 -> 17000 | E40: =D40*C40 -> 34000 | G40: 3 | H40: 2 | I40: =(15*(600+150+250))+2000 -> 17000 | J40: =I40*H40 -> 34000
B41: ITEM | C41: QUANTITY | D41: PRICE | E41: TOTAL | G41: ITEM | H41: QUANTITY | I41: PRICE | J41: TOTAL
B42: PLUMBING WORKS | E42: =D42*C42 -> 0 | G42: PLUMBING WORKS | J42: =I42*H42 -> 0
...

Sheet DASHBOARD (4)
A1: SELLING PHASE NAME | B1: R 1
A3: Row Labels | B3: Count of Unit Selling Area
A4: 75 | B4: 3
A5: 106 | B5: 6
A6: 108 | B6: 2
A7: 110 | B7: 9
A8: 111 | B8: 5
A9: 112 | B9: 1
A10: 116 | B10: 8
A11: 117 | B11: 6
A12: 119 | B12: 5
A13: 120 | B13: 2
A14: 121 | B14: 5
A15: 122 | B15: 1
... A35: 344 | B35: 2
A36: Grand Total | B36: 144

Sheet prem cat. total dash
A1: Premium Category | B1: Count of PREMIUM CATEGORY | C1: Min of TOTAL PREMIUM % | D1: Max of TOTAL PREMIUM %
A2: A | B2: 204 | C2: 0.73 | D2: 0.965
A3: B | B3: 253 | C3: 0.505 | D3: 0.729
A4: C | B4: 345 | C4: 0.275 | D4: 0.495
A5: HOTEL | B5: 56 | C5: 0.285 | D5: 0.65
A6: Grand Total | B6: 858 | C6: 0.275 | D6: 0.965

Sheet DASHBOARD (2)
A1: SELLING PHASE NAME | B1: R 1
A3: Row Labels | B3: Count of Unit Selling Area | C3: Min of TOTAL PREMIUM % | D3: Max of TOTAL PREMIUM %
A4: 75 | B4: 3 | C4: 0.355 | D4: 0.355
A5: 106 | B5: 6 | C5: 0.355 | D5: 0.355
A6: 108 | B6: 2 | C6: 0.325 | D6: 0.345
A7: 110 | B7: 9 | C7: 0.355 | D7: 0.745
A8: 111 | B8: 5 | C8: 0.275 | D8: 0.585
A9: 112 | B9: 1 | C9: 0.505 | D9: 0.505
A10: 116 | B10: 8 | C10: 0.325 | D10: 0.355
A11: 117 | B11: 6 | C11: 0.345 | D11: 0.585
A12: 119 | B12: 5 | C12: 0.515 | D12: 0.745
A13: 120 | B13: 2 | C13: 0.355 | D13: 0.355
A14: 121 | B14: 5 | C14: 0.345 | D14: 0.585
A15: 122 | B15: 1 | C15: 0.555 | D15: 0.555
... A35: 344 | B35: 2 | C35: 0.685 | D35: 0.735
A36: Grand Total | B36: 144 | C36: 0.275 | D36: 0.745

Sheet A
L4: BLD No. | M4: A' - ( 1 )
L5: View | M5: Garden | O5: Garden | Q5: Garden | S5: Garden
L7: APT | M7: 3 | N7: 2 | O7: 3 | P7: 2 | Q7: 3 | R7: 2 | S7: 4 | T7: 3 | U7: 2
M8: 4 | N8: 1 | O8: 4 | P8: 1 | Q8: 4 | R8: 1 | S8: 5 | T8: 6 | U8: 1
L10: View | M10: Street | O10: Street | Q10: Street | S10: Street
A11: Type A'
A12: BLD Type | B12: Plot | C12: BLD No. | D12: Floor | E12: UNIT | F12: Unit Net Area | G12: Unit Gross | H12: PRIVET GARDEN | I12: Total Gross Area | J12: Service Area
A13: A' | B13: 1 | C13: A5 | D13: 0 | E13: =[2]A!E10 -> 1 | F13: =[2]A!F10 -> 69.17 | G13: =[2]A!G10 -> 88.3224 | H13: 24.4619 | I13: =SUM(G13:G40) -> 2208.06 | J13: =[2]A!I10 -> 125.92 | K13: =[2]A!J10 -> 441.66
E14: =[2]A!E11 -> 2 | F14: =[2]A!F11 -> 68.59 | G14: =[2]A!G11 -> 87.581804 | H14: 35.7856
E15: =[2]A!E12 -> 3 | F15: =[2]A!F12 -> 51.02 | G15: =[2]A!G12 -> 65.146868 | H15: 34.8891
E16: =[2]A!E13 -> 4 | F16: =[2]A!F13 -> 63.16 | G16: =[2]A!G13 -> 80.648298 | H16: 37.7172
E17: =[2]A!E14 -> 5 | F17: =[2]A!F14 -> 63.79 | G17: =[2]A!G14 -> 81.452738 | H17: 24.6688
D18: 1 | E18: =[2]A!E15 -> 1 | F18: =[2]A!F15 -> 69.17 | G18: =[2]A!G15 -> 88.3224 | J18: =[2]A!I15 -> 125.92 | K18: =[2]A!J15 -> 440.97
E19: =[2]A!E16 -> 2 | F19: =[2]A!F16 -> 68.59 | G19: =[2]A!G16 -> 87.581804
E20: =[2]A!E17 -> 3 | F20: =[2]A!F17 -> 51.02 | G20: =[2]A!G17 -> 65.146868
E21: =[2]A!E18 -> 4 | F21: =[2]A!F18 -> 62.9 | G21: =[2]A!G18 -> 80.316307
E22: =[2]A!E19 -> 5 | F22: =[2]A!F19 -> 63.79 | G22: =[2]A!G19 -> 81.452738
D23: 2 | E23: =[2]A!E20 -> 1 | F23: =[2]A!F20 -> 68.91 | G23: =[2]A!G20 -> 87.990409 | J23: =[2]A!I20 -> 75.75 | K23: =[2]A!J20 -> 442.77
E24: =[2]A!E21 -> 2 | F24: =[2]A!F21 -> 68.89 | G24: =[2]A!G21 -> 87.964871
E25: =[2]A!E22 -> 3 | F25: =[2]A!F22 -> 51.48 | G25: =[2]A!G22 -> 65.734237
E26: =[2]A!E23 -> 4 | F26: =[2]A!F23 -> 63.11 | G26: =[2]A!G23 -> 80.584454
E27: =[2]A!E24 -> 5 | F27: =[2]A!F24 -> 63.16 | G27: =[2]A!G24 -> 80.648298
E28: =[2]A!E25 -> 6 | F28: =[2]A!F25 -> 51.5 | G28: =[2]A!G25 -> 65.759774
D29: 3 | E29: =[2]A!E26 -> 1 | F29: =[2]A!F26 -> 68.62 | G29: =[2]A!G26 -> 87.620111 | J29: =[2]A!I26 -> 75.75 | K29: =[2]A!J26 -> 440.39
E30: =[2]A!E27 -> 2 | F30: =[2]A!F27 -> 68.6 | G30: =[2]A!G27 -> 87.594573
E31: =[2]A!E28 -> 3 | F31: =[2]A!F28 -> 50.89 | G31: =[2]A!G28 -> 64.980872
E32: =[2]A!E29 -> 4 | F32: =[2]A!F29 -> 62.84 | G32: =[2]A!G29 -> 80.239694
E33: =[2]A!E30 -> 5 | F33: =[2]A!F30 -> 62.86 | G33: =[2]A!G30 -> 80.265232
E34: =[2]A!E31 -> 6 | F34: =[2]A!F31 -> 50.89 | G34: =[2]A!G31 -> 64.980872
D35: 4 | E35: =[2]A!E32 -> 1 | F35: =[2]A!F32 -> 68.68 | G35: =[2]A!G32 -> 87.696724 | J35: =[2]A!I32 -> 75.75 | K35: =[2]A!J32 -> 442.27
E36: =[2]A!E33 -> 2 | F36: =[2]A!F33 -> 68.68 | G36: =[2]A!G33 -> 87.696724
E37: =[2]A!E34 -> 3 | F37: =[2]A!F34 -> 51.5 | G37: =[2]A!G34 -> 65.759774
E38: =[2]A!E35 -> 4 | F38: =[2]A!F35 -> 62.97 | G38: =[2]A!G35 -> 80.405689
E39: =[2]A!E36 -> 5 | F39: =[2]A!F36 -> 62.97 | G39: =[2]A!G36 -> 80.405689
E40: =[2]A!E37 -> 6 | F40: =[2]A!F37 -> 51.5 | G40: =[2]A!G37 -> 65.759774
A41: Total | F41: =SUM(F13:F40) -> 1729.25 | I41: =K13+K18+K23+K29+K35 -> 2208.06 | J41: =J35+J29+J23+J18+J13 -> 479.09
F42: =I41/F41 -> 1.2768888 | J42: =(J13+J18+J23+J29+J35)/I41 -> 0.21697327
A45: Type A'
A46: BLD Type | B46: Plot | C46: BLD No. | D46: Floor | E46: UNIT | F46: Unit Net Area | G46: Unit Gross | H46: PRIVET GARDEN | I46: Total Gross Area | J46: Service Area
A47: A' | B47: 1 | C47: A6 | D47: 0 | E47: =[2]A!E44 -> 1 | F47: =[2]A!F44 -> 60.98 | G47: =[2]A!G44 -> 66.845202 | H47: 23.8181 | I47: =SUM(G47:G66) -> 1994.46 | J47: =J99 -> 48.87 | K47: =[2]A!J44 -> 396.25
...

Sheet Regent's Square
A4: BLD Type | B4: Plot | C4: BLD No. | D4: Floor | E4: UNIT | F4: Unit Number | G4: Unit Net Area | H4: Unit Gross Area | I4: Unit Selling Area | J4: Private Garden Area | K4: Total Gross Area | L4: Service Area
A5: A | B5: 15 | C5: A1 | D5: 0 | E5: 1 | F5: =LEFT(C5,2)&D5&E5 -> A101 | G5: 110.32 | H5: 120.40866 | I5: =G5*1.22 -> 134.5904 | J5: 42.7795 | K5: =SUM(H5:H24) -> 2124.2 | L5: 48.87
C6: A1 | D6: 0 | E6: 2 | F6: =LEFT(C6,2)&D6&E6 -> A102 | G6: 110.14 | H6: 120.2122 | I6: =G6*1.22 -> 134.3708 | J6: 59.4821
C7: A1 | D7: 0 | E7: 3 | F7: =LEFT(C7,2)&D7&E7 -> A103 | G7: 89.96 | H7: 98.186758 | I7: =G7*1.22 -> 109.7512 | J7: 50.5078
C8: A1 | D8: 0 | E8: 4 | F8: =LEFT(C8,2)&D8&E8 -> A104 | G8: 60.98 | H8: 66.556564 | I8: =G8*1.22 -> 74.3956 | J8: 23.8084
C9: A1 | D9: 1 | E9: 1 | F9: =LEFT(C9,2)&D9&E9 -> A111 | G9: 110.61 | H9: 120.72518 | I9: =G9*1.22 -> 134.9442 | L9: 35.73
C10: A1 | D10: 1 | E10: 2 | F10: =LEFT(C10,2)&D10&E10 -> A112 | G10: 110.14 | H10: 120.2122 | I10: =G10*1.22 -> 134.3708
C11: A1 | D11: 1 | E11: 3 | F11: =LEFT(C11,2)&D11&E11 -> A113 | G11: 89.05 | H11: 97.193539 | I11: =G11*1.22 -> 108.641
C12: A1 | D12: 1 | E12: 4 | F12: =LEFT(C12,2)&D12&E12 -> A114 | G12: 61.82 | H12: 67.473381 | I12: =G12*1.22 -> 75.4204
C13: A1 | D13: 2 | E13: 1 | F13: =LEFT(C13,2)&D13&E13 -> A121 | G13: 112.2 | H13: 122.46059 | I13: =G13*1.22 -> 136.884 | L13: 29.85
C14: A1 | D14: 2 | E14: 2 | F14: =LEFT(C14,2)&D14&E14 -> A122 | G14: 112.2 | H14: 122.46059 | I14: =G14*1.22 -> 136.884
C15: A1 | D15: 2 | E15: 3 | F15: =LEFT(C15,2)&D15&E15 -> A123 | G15: 90.91 | H15: 99.223635 | I15: =G15*1.22 -> 110.9102
C16: A1 | D16: 2 | E16: 4 | F16: =LEFT(C16,2)&D16&E16 -> A124 | G16: 90.91 | H16: 99.223635 | I16: =G16*1.22 -> 110.9102
C17: A1 | D17: 3 | E17: 1 | F17: =LEFT(C17,2)&D17&E17 -> A131 | G17: 110.14 | H17: 120.2122 | I17: =G17*1.22 -> 134.3708 | L17: 29.85
C18: A1 | D18: 3 | E18: 2 | F18: =LEFT(C18,2)&D18&E18 -> A132 | G18: 110.14 | H18: 120.2122 | I18: =G18*1.22 -> 134.3708
C19: A1 | D19: 3 | E19: 3 | F19: =LEFT(C19,2)&D19&E19 -> A133 | G19: 89.05 | H19: 97.193539 | I19: =G19*1.22 -> 108.641
C20: A1 | D20: 3 | E20: 4 | F20: =LEFT(C20,2)&D20&E20 -> A134 | G20: 89.05 | H20: 97.193539 | I20: =G20*1.22 -> 108.641
C21: A1 | D21: 4 | E21: 1 | F21: =LEFT(C21,2)&D21&E21 -> A141 | G21: 110.18 | H21: 120.25586 | I21: =G21*1.22 -> 134.4196 | L21: 29.85
C22: A1 | D22: 4 | E22: 2 | F22: =LEFT(C22,2)&D22&E22 -> A142 | G22: 110.18 | H22: 120.25586 | I22: =G22*1.22 -> 134.4196
C23: A1 | D23: 4 | E23: 3 | F23: =LEFT(C23,2)&D23&E23 -> A143 | G23: 89.12 | H23: 97.269941 | I23: =G23*1.22 -> 108.7264
C24: A1 | D24: 4 | E24: 4 | F24: =LEFT(C24,2)&D24&E24 -> A144 | G24: 89.12 | H24: 97.269941 | I24: =G24*1.22 -> 108.7264
A25: Total | G25: 1946.22 | I25: =SUM(I5:I24) -> 2374.3884 | K25: =SUM(K5) -> 2124.2 | L25: =L21+L17+L13+L9+L5 -> 174.15
G26: =K25/G25 -> 1.0914491 | L26: =(L5+L9+L13+L17+L21)/K25 -> 0.081983806
A29: Type A
A30: BLD Type | B30: Plot | C30: BLD No. | D30: Floor | E30: UNIT | F30: Unit Number | G30: Unit Net Area | H30: Unit Gross Area | I30: Unit Selling Area | J30: Private Garden Area | K30: Total Gross Area | L30: Service Area
A31: A | B31: 15 | C31: A2 | D31: 0 | E31: 1 | F31: =LEFT(C31,2)&D31&E31 -> A201 | G31: 60.98 | H31: 66.8441 | I31: =G31*1.22 -> 74.3956 | J31: 23.8084 | K31: =SUM(I31:I50) -> 2219.7778 | L31: =L5 -> 48.87
C32: A2 | D32: 0 | E32: 2 | F32: =LEFT(C32,2)&D32&E32 -> A202 | G32: 89.96 | H32: 98.610941 | I32: =G32*1.22 -> 109.7512 | J32: 50.5039
C33: A2 | D33: 0 | E33: 3 | F33: =LEFT(C33,2)&D33&E33 -> A203 | G33: 97.98 | H33: 107.40218 | I33: =G33*1.22 -> 119.5356 | J33: 50.7053
C34: A2 | D34: 0 | E34: 4 | F34: =LEFT(C34,2)&D34&E34 -> A204 | G34: 98.17 | H34: 107.61045 | I34: =G34*1.22 -> 119.7674 | J34: 31.6139
C35: A2 | D35: 1 | E35: 1 | F35: =LEFT(C35,2)&D35&E35 -> A211 | G35: 61.82 | H35: 67.764878 | I35: =G35*1.22 -> 75.4204 | L35: =L9 -> 35.73
C36: A2 | D36: 1 | E36: 2 | F36: =LEFT(C36,2)&D36&E36 -> A212 | G36: 89.05 | H36: 97.613432 | I36: =G36*1.22 -> 108.641
C37: A2 | D37: 1 | E37: 3 | F37: =LEFT(C37,2)&D37&E37 -> A213 | G37: 97.06 | H37: 106.39371 | I37: =G37*1.22 -> 118.4132
C38: A2 | D38: 1 | E38: 4 | F38: =LEFT(C38,2)&D38&E38 -> A214 | G38: 97.09 | H38: 106.42659 | I38: =G38*1.22 -> 118.4498
C39: A2 | D39: 2 | E39: 1 | F39: =LEFT(C39,2)&D39&E39 -> A221 | G39: 90.91 | H39: 99.652297 | I39: =G39*1.22 -> 110.9102 | L39: =L13 -> 29.85
C40: A2 | D40: 2 | E40: 2 | F40: =LEFT(C40,2)&D40&E40 -> A222 | G40: 90.91 | H40: 99.652297 | I40: =G40*1.22 -> 110.9102
C41: A2 | D41: 2 | E41: 3 | F41: =LEFT(C41,2)&D41&E41 -> A223 | G41: 98.95 | H41: 108.46546 | I41: =G41*1.22 -> 120.719
C42: A2 | D42: 2 | E42: 4 | F42: =LEFT(C42,2)&D42&E42 -> A224 | G42: 98.95 | H42: 108.46546 | I42: =G42*1.22 -> 120.719
C43: A2 | D43: 3 | E43: 1 | F43: =LEFT(C43,2)&D43&E43 -> A231 | G43: 89.05 | H43: 97.613432 | I43: =G43*1.22 -> 108.641 | L43: =L17 -> 29.85
C44: A2 | D44: 3 | E44: 2 | F44: =LEFT(C44,2)&D44&E44 -> A232 | G44: 89.05 | H44: 97.613432 | I44: =G44*1.22 -> 108.641
C45: A2 | D45: 3 | E45: 3 | F45: =LEFT(C45,2)&D45&E45 -> A233 | G45: 97.09 | H45: 106.42659 | I45: =G45*1.22 -> 118.4498
...

Sheet FACTS
A1: DATE | B1: SELLING PHASE | C1: PHASES ESCALLATION RATES | D1: PLANNED PHASES SELLING % | E1: PLANNED PHASES SELLING AREA | F1: CATEGORY (A) (SELLING PHASE AREA) | G1: CATEGORY (B) (SELLING PHASE AREA) | H1: CATEGORY (C) (SELLING PHASE AREA) | J1: PARKING PRICE | K1: PHASE (BUILDING) STARTING PRICE | L1: PHASE (BUILDING) CLOSING PRICE | M1: PHASE AVERAGE PRICE | N1: PHASE PREMIUM RANGE | O1: PREMIUM RANGE % | P1: BASIC PRICE INCREASE | Q1: PREMIUM PRICE INCREASE | R1: PHASE INCREASE % | S1: MAINTENANCE % | T1: GARDEN PRICE %
A2: 45200 | B2: R 1 | C2: 0 | D2: 0.17 | E2: =131531*D2 -> 22360.27 | F2: =GETPIVOTDATA("Sum of Unit Selling Area2",PIVOT!$A$227,"PREMIUM CATEGORY","A")*E2 -> 6579.5378 | G2: =GETPIVOTDATA("Sum of Unit Selling Area2",PIVOT!$A$227,"PREMIUM CATEGORY","B")*E2 -> 7320.0161 | H2: =GETPIVOTDATA("Sum of Unit Selling Area2",PIVOT!$A$227,"PREMIUM CATEGORY","C")*E2 -> 8460.7162 | J2: 200000 | K2: 42500 | L2: 47500 | M2: =AVERAGE(K2:L2) -> 45000 | N2: =L2-K2 -> 5000 | O2: =N2/K2 -> 0.11764706 | P2: =K2-K2 -> 0 | Q2: =N2-N2 -> 0 | R2: =C2-C2 -> 0 | S2: 0.085 | T2: 0.33
A3: =EDATE(A2,3) -> 45292 | B3: R 2 | C3: 0.025 | D3: 0.07 | E3: =131531*D3 -> 9207.17 | F3: =GETPIVOTDATA("Sum of Unit Selling Area2",PIVOT!$A$227,"PREMIUM CATEGORY","A")*E3 -> 2709.2214 | G3: =GETPIVOTDATA("Sum of Unit Selling Area2",PIVOT!$A$227,"PREMIUM CATEGORY","B")*E3 -> 3014.1243 | H3: =GETPIVOTDATA("Sum of Unit Selling Area2",PIVOT!$A$227,"PREMIUM CATEGORY","C")*E3 -> 3483.8243 | J3: =$J$2*(1+C3) -> 205000 | K3: =$K$2*(1+C3) -> 43562.5 | L3: =$L$2*(1+C3) -> 48687.5 | M3: =AVERAGE(K3:L3) -> 46125 | N3: =L3-K3 -> 5125 | O3: =N3/K3 -> 0.11764706 | P3: =K3-K2 -> 1062.5 | Q3: =N3-$N$2 -> 125 | R3: =C3-C2 -> 0.025 | S3: 0.085 | T3: 0.33
A4: =EDATE(A3,3) -> 45383 | B4: R 3 | C4: 0.05 | D4: 0.07 | E4: =131531*D4 -> 9207.17 | F4: =GETPIVOTDATA("Sum of Unit Selling Area2",PIVOT!$A$227,"PREMIUM CATEGORY","A")*E4 -> 2709.2214 | G4: =GETPIVOTDATA("Sum of Unit Selling Area2",PIVOT!$A$227,"PREMIUM CATEGORY","B")*E4 -> 3014.1243 | H4: =GETPIVOTDATA("Sum of Unit Selling Area2",PIVOT!$A$227,"PREMIUM CATEGORY","C")*E4 -> 3483.8243 | J4: =$J$2*(1+C4) -> 210000 | K4: =$K$2*(1+C4) -> 44625 | L4: =$L$2*(1+C4) -> 49875 | M4: =AVERAGE(K4:L4) -> 47250 | N4: =L4-K4 -> 5250 | O4: =N4/K4 -> 0.11764706 | P4: =K4-K3 -> 1062.5 | Q4: =N4-$N$2 -> 250 | R4: =C4-C3 -> 0.025 | S4: 0.085 | T4: 0.33
A5: =EDATE(A4,3) -> 45474 | B5: R 4 | C5: 0.075 | D5: 0.11 | E5: =131531*D5 -> 14468.41 | F5: =GETPIVOTDATA("Sum of Unit Selling Area2",PIVOT!$A$227,"PREMIUM CATEGORY","A")*E5 -> 4257.348 | G5: =GETPIVOTDATA("Sum of Unit Selling Area2",PIVOT!$A$227,"PREMIUM CATEGORY","B")*E5 -> 4736.481 | H5: =GETPIVOTDATA("Sum of Unit Selling Area2",PIVOT!$A$227,"PREMIUM CATEGORY","C")*E5 -> 5474.581 | J5: =$J$2*(1+C5) -> 215000 | K5: =$K$2*(1+C5) -> 45687.5 | L5: =$L$2*(1+C5) -> 51062.5 | M5: =AVERAGE(K5:L5) -> 48375 | N5: =L5-K5 -> 5375 | O5: =N5/K5 -> 0.11764706 | P5: =K5-K4 -> 1062.5 | Q5: =N5-$N$2 -> 375 | R5: =C5-C4 -> 0.025 | S5: 0.085 | T5: 0.33
A6: =EDATE(A5,3) -> 45566 | B6: R 5 | C6: 0.1 | D6: 0.08 | E6: =131531*D6 -> 10522.48 | F6: =GETPIVOTDATA("Sum of Unit Selling Area2",PIVOT!$A$227,"PREMIUM CATEGORY","A")*E6 -> 3096.2531 | G6: =GETPIVOTDATA("Sum of Unit Selling Area2",PIVOT!$A$227,"PREMIUM CATEGORY","B")*E6 -> 3444.7134 | H6: =GETPIVOTDATA("Sum of Unit Selling Area2",PIVOT!$A$227,"PREMIUM CATEGORY","C")*E6 -> 3981.5135 | J6: =$J$2*(1+C6) -> 220000 | K6: =$K$2*(1+C6) -> 46750 | L6: =$L$2*(1+C6) -> 52250 | M6: =AVERAGE(K6:L6) -> 49500 | N6: =L6-K6 -> 5500 | O6: =N6/K6 -> 0.11764706 | P6: =K6-K5 -> 1062.5 | Q6: =N6-$N$2 -> 500 | R6: =C6-C5 -> 0.025 | S6: 0.085 | T6: 0.33
A7: =EDATE(A6,3) -> 45658 | B7: R 6 | C7: 0.14 | D7: 0.07 | E7: =131531*D7 -> 9207.17 | F7: =GETPIVOTDATA("Sum of Unit Selling Area2",PIVOT!$A$227,"PREMIUM CATEGORY","A")*E7 -> 2709.2214 | G7: =GETPIVOTDATA("Sum of Unit Selling Area2",PIVOT!$A$227,"PREMIUM CATEGORY","B")*E7 -> 3014.1243 | H7: =GETPIVOTDATA("Sum of Unit Selling Area2",PIVOT!$A$227,"PREMIUM CATEGORY","C")*E7 -> 3483.8243 | J7: =$J$2*(1+C7) -> 228000 | K7: =$K$2*(1+C7) -> 48450 | L7: =$L$2*(1+C7) -> 54150 | M7: =AVERAGE(K7:L7) -> 51300 | N7: =L7-K7 -> 5700 | O7: =N7/K7 -> 0.11764706 | P7: =K7-K6 -> 1700 | Q7: =N7-$N$2 -> 700 | R7: =C7-C6 -> 0.04 | S7: 0.085 | T7: 0.33
A8: =EDATE(A7,3) -> 45748 | B8: R 7 | C8: 0.18 | D8: 0.08 | E8: =131531*D8 -> 10522.48 | F8: =GETPIVOTDATA("Sum of Unit Selling Area2",PIVOT!$A$227,"PREMIUM CATEGORY","A")*E8 -> 3096.2531 | G8: =GETPIVOTDATA("Sum of Unit Selling Area2",PIVOT!$A$227,"PREMIUM CATEGORY","B")*E8 -> 3444.7134 | H8: =GETPIVOTDATA("Sum of Unit Selling Area2",PIVOT!$A$227,"PREMIUM CATEGORY","C")*E8 -> 3981.5135 | J8: =$J$2*(1+C8) -> 236000 | K8: =$K$2*(1+C8) -> 50150 | L8: =$L$2*(1+C8) -> 56050 | M8: =AVERAGE(K8:L8) -> 53100 | N8: =L8-K8 -> 5900 | O8: =N8/K8 -> 0.11764706 | P8: =K8-K7 -> 1700 | Q8: =N8-$N$2 -> 900 | R8: =C8-C7 -> 0.04 | S8: 0.085 | T8: 0.33
A9: =EDATE(A8,3) -> 45839 | B9: R 8 | C9: 0.22 | D9: 0.12 | E9: =131531*D9 -> 15783.72 | F9: =GETPIVOTDATA("Sum of Unit Selling Area2",PIVOT!$A$227,"PREMIUM CATEGORY","A")*E9 -> 4644.3796 | G9: =GETPIVOTDATA("Sum of Unit Selling Area2",PIVOT!$A$227,"PREMIUM CATEGORY","B")*E9 -> 5167.0702 | H9: =GETPIVOTDATA("Sum of Unit Selling Area2",PIVOT!$A$227,"PREMIUM CATEGORY","C")*E9 -> 5972.2702 | J9: =$J$2*(1+C9) -> 244000 | K9: =$K$2*(1+C9) -> 51850 | L9: =$L$2*(1+C9) -> 57950 | M9: =AVERAGE(K9:L9) -> 54900 | N9: =L9-K9 -> 6100 | O9: =N9/K9 -> 0.11764706 | P9: =K9-K8 -> 1700 | Q9: =N9-$N$2 -> 1100 | R9: =C9-C8 -> 0.04 | S9: 0.085 | T9: 0.33
A10: =EDATE(A9,3) -> 45931 | B10: R 9 | C10: 0.26 | D10: 0.08 | E10: =131531*D10 -> 10522.48 | F10: =GETPIVOTDATA("Sum of Unit Selling Area2",PIVOT!$A$227,"PREMIUM CATEGORY","A")*E10 -> 3096.2531 | G10: =GETPIVOTDATA("Sum of Unit Selling Area2",PIVOT!$A$227,"PREMIUM CATEGORY","B")*E10 -> 3444.7134 | H10: =GETPIVOTDATA("Sum of Unit Selling Area2",PIVOT!$A$227,"PREMIUM CATEGORY","C")*E10 -> 3981.5135 | J10: =$J$2*(1+C10) -> 252000 | K10: =$K$2*(1+C10) -> 53550 | L10: =$L$2*(1+C10) -> 59850 | M10: =AVERAGE(K10:L10) -> 56700 | N10: =L10-K10 -> 6300 | O10: =N10/K10 -> 0.11764706 | P10: =K10-K9 -> 1700 | Q10: =N10-$N$2 -> 1300 | R10: =C10-C9 -> 0.04 | S10: 0.085 | T10: 0.33
A11: =EDATE(A10,3) -> 46023 | B11: R 10 | C11: 0.32 | D11: 0.03 | E11: =131531*D11 -> 3945.93 | F11: =GETPIVOTDATA("Sum of Unit Selling Area2",PIVOT!$A$227,"PREMIUM CATEGORY","A")*E11 -> 1161.0949 | G11: =GETPIVOTDATA("Sum of Unit Selling Area2",PIVOT!$A$227,"PREMIUM CATEGORY","B")*E11 -> 1291.7675 | H11: =GETPIVOTDATA("Sum of Unit Selling Area2",PIVOT!$A$227,"PREMIUM CATEGORY","C")*E11 -> 1493.0676 | J11: =$J$2*(1+C11) -> 264000 | K11: =$K$2*(1+C11) -> 56100 | L11: =$L$2*(1+C11) -> 62700 | M11: =AVERAGE(K11:L11) -> 59400 | N11: =L11-K11 -> 6600 | O11: =N11/K11 -> 0.11764706 | P11: =K11-K10 -> 2550 | Q11: =N11-$N$2 -> 1600 | R11: =C11-C10 -> 0.06 | S11: 0.085 | T11: 0.33
A12: =EDATE(A11,3) -> 46113 | B12: R 11 | C12: 0.38 | D12: 0.03 | E12: =131531*D12 -> 3945.93 | F12: =GETPIVOTDATA("Sum of Unit Selling Area2",PIVOT!$A$227,"PREMIUM CATEGORY","A")*E12 -> 1161.0949 | G12: =GETPIVOTDATA("Sum of Unit Selling Area2",PIVOT!$A$227,"PREMIUM CATEGORY","B")*E12 -> 1291.7675 | H12: =GETPIVOTDATA("Sum of Unit Selling Area2",PIVOT!$A$227,"PREMIUM CATEGORY","C")*E12 -> 1493.0676 | J12: =$J$2*(1+C12) -> 276000 | K12: =$K$2*(1+C12) -> 58650 | L12: =$L$2*(1+C12) -> 65550 | M12: =AVERAGE(K12:L12) -> 62100 | N12: =L12-K12 -> 6900 | O12: =N12/K12 -> 0.11764706 | P12: =K12-K11 -> 2550 | Q12: =N12-$N$2 -> 1900 | R12: =C12-C11 -> 0.06 | S12: 0.085 | T12: 0.33
A13: =EDATE(A12,3) -> 46204 | B13: R 12 | C13: 0.45 | D13: 0.09 | E13: =131531*D13 -> 11837.79 | F13: =GETPIVOTDATA("Sum of Unit Selling Area2",PIVOT!$A$227,"PREMIUM CATEGORY","A")*E13 -> 3483.2847 | G13: =GETPIVOTDATA("Sum of Unit Selling Area2",PIVOT!$A$227,"PREMIUM CATEGORY","B")*E13 -> 3875.3026 | H13: =GETPIVOTDATA("Sum of Unit Selling Area2",PIVOT!$A$227,"PREMIUM CATEGORY","C")*E13 -> 4479.2027 | J13: =$J$2*(1+C13) -> 290000 | K13: =$K$2*(1+C13) -> 61625 | L13: =$L$2*(1+C13) -> 68875 | M13: =AVERAGE(K13:L13) -> 65250 | N13: =L13-K13 -> 7250 | O13: =N13/K13 -> 0.11764706 | P13: =K13-K12 -> 2975 | Q13: =N13-$N$2 -> 2250 | R13: =C13-C12 -> 0.07 | S13: 0.085 | T13: 0.33
A14: =EDATE(A8,3) -> 45839 | B14: RH | C14: =C9 -> 0.22 | D14: 1 | E14: 4434 | F14: 0 | G14: 2808 | H14: 1626 | J14: =J9 -> 244000 | K14: =K9+25000 -> 76850 | L14: =L9+25000 -> 82950 | M14: =M9+25000 -> 79900 | N14: =L14-K14 -> 6100 | S14: 0.2 | T14: 0.33
F15: COMMULATIVE | G15: COMMULATIVE | H15: COMMULATIVE
A16: CATEGORY | B16: AREA RANGE | C16: NO. OF CAR PARKING | E16: R1 | F16: =F2 -> 6579.5378 | G16: =G2 -> 7320.0161 | H16: =H2 -> 8460.7162
A17: HOTEL | B17: 0-89M2 | C17: 1 | E17: R2 | F17: =F16+F3 -> 9288.7592 | G17: =G16+G3 -> 10334.14 | H17: =H16+H3 -> 11944.54
A18: A | B18: 0-89M2 | C18: 1 | E18: R3 | F18: =F17+F4 -> 11997.981 | G18: =G17+G4 -> 13348.265 | H18: =H17+H4 -> 15428.365
A19: B | B19: 90-122M2 | C19: 1 | E19: R4 | F19: =F18+F5 -> 16255.329 | G19: =G18+G5 -> 18084.746 | H19: =H18+H5 -> 20902.946
A20: C | B20: 123-160M2 | C20: 2 | E20: R5 | F20: =F19+F6 -> 19351.582 | G20: =G19+G6 -> 21529.459 | H20: =H19+H6 -> 24884.459
A21: D | B21: 161-185M2 | C21: 2 | E21: R6 | F21: =F20+F7 -> 22060.803 | G21: =G20+G7 -> 24543.583 | H21: =H20+H7 -> 28368.284
A22: E | B22: 186-230M2 | C22: 2 | E22: R7 | F22: =F21+F8 -> 25157.056 | G22: =G21+G8 -> 27988.297 | H22: =H21+H8 -> 32349.797
A23: F | B23: 230-350M2 | C23: 2 | E23: R8 | F23: =F22+F9 -> 29801.436 | G23: =G22+G9 -> 33155.367 | H23: =H22+H9 -> 38322.067
E24: R9 | F24: =F23+F10 -> 32897.689 | G24: =G23+G10 -> 36600.08 | H24: =H23+H10 -> 42303.581
E25: R10 | F25: =F24+F11 -> 34058.784 | G25: =G24+G11 -> 37891.848 | H25: =H24+H11 -> 43796.648
E26: R11 | F26: =F25+F12 -> 35219.879 | G26: =G25+G12 -> 39183.615 | H26: =H25+H12 -> 45289.716
E27: R12 | F27: =F26+F13 -> 38703.163 | G27: =G26+G13 -> 43058.918 | H27: =H26+H13 -> 49768.919

Sheet PREMIUM TABLES
G3: FLOOR PREMIUM
G4: FLOOR NAME | H4: PREMIUM %
G5: GROUND | H5: 0.05
G6: FIRST | H6: 0.07
G7: SECOND | H7: 0.11
G8: THIRD | H8: 0.15
G9: FORTH | H9: 0.06
G11: SELLING PHASES
G12: BUILDING NO. | H12: PHASE NO.
G13: A1 | H13: R1
G14: A2 | H14: R2
G15: A3 | H15: R2
G16: A4 | H16: R1
G17: B1 | H17: R3
G18: B2 | H18: R4
G19: B3 | H19: R4
G20: B4 | H20: R3
G21: C1 | H21: R4
G22: C2 | H22: R7
G23: C3 | H23: R3
... G55: F5 | H55: R6
G57: INTERNAL LOCATION
G58: BUILDING NO. | H58: PHASE NO.
G59: A1 | H59: CV
G60: A2 | H60: M
G61: A3 | H61: M
G62: A4 | H62: CV
G63: A5 | H63: CV
G64: A6 | H64: M
G65: A7 | H65: M
G66: A8 | H66: CV
G67: B1 | H67: CV
G68: B2 | H68: CV
G69: B3 | H69: CV
... G101: E5 | H101: C3
G105: CONSTRUCTION PHASES
G106: BUILDING NO. | H106: PHASE NO.
G107: A1 | H107: C1
G108: A2 | H108: C1
G109: A3 | H109: C1
...

Sheet C PHASES
G8: CONSTRUCTION PHASES
G9: Column1 | H9: Column2
G10: BUILDING NO. | H10: PHASE NO.
G11: A1 | H11: C1
G12: A2 | H12: C1
G13: A3 | H13: C1
G14: A4 | H14: C1
G15: A5 | H15: C1
G16: A6 | H16: C1
G17: A7 | H17: C1
G18: A8 | H18: C1
G19: B1 | H19: C1
G20: B2 | H20: C1
... G53: E5 | H53: C3
L87: A1 | M87: B6 | N87: D1
L88: A2 | M88: B7 | N88: D2
L89: A3 | M89: B8 | N89: D3
L90: A4 | M90: B9 | N90: D4
L91: A5 | M91: B10 | N91: D5
L92: A6 | M92: B11 | N92: E1
L93: A7 | M93: B12 | N93: E2
L94: A8 | M94: B13 | N94: E3
L95: B1 | M95: B14 | N95: E4
L96: B2 | M96: C1 | N96: E5
L97: B3 | M97: C2
L98: B4 | M98: C3
L99: B5 | M99: C4
L100: B15 | M100: C5
L101: B16 | M101: C6
L102: B17
L103: B18
L104: B19
I107: CONSTRUCTION PHASE | J107: DELIVERY TIME | K107: DELIVERY PERIOD
I108: C1 | J108: 45839 | K108: 3 YEARS
I109: C2 | J109: 46204
I110: C3 | J110: 46569
I113: R 1 | J113: 45170
I114: R 2 | J114: 45292
I115: R 3 | J115: =EDATE(J114,3) -> 45383
I116: R 4 | J116: =EDATE(J115,3) -> 45474
...

Sheet PIVOT
A3: PREMIUM % | B3: Count of UnitS
A4: 0.275 | B4: 1
A5: 0.285 | B5: 2
A6: 0.31 | B6: 1
A7: 0.32 | B7: 2
A8: 0.32 | B8: 2
A9: 0.325 | B9: 2
A10: 0.325 | B10: 4
A11: 0.33 | B11: 1
A12: 0.33 | B12: 2
A13: 0.335 | B13: 3
A14: 0.34 | B14: 5
A15: 0.345 | B15: 6
... A220: 0.72 | B220: 1
A221: Grand Total | B221: 858
A227: PREMIUM % | B227: Count of Unit Number | C227: Sum of Unit Selling Area | D227: Sum of Unit Selling Area2
A228: A | B228: 204 | C228: 38732 | D228: 0.29425127
A229: B | B229: 253 | C229: 43091 | D229: 0.32736707
A230: C | B230: 345 | C230: 49806 | D230: 0.37838166
A231: Grand Total | B231: 802 | C231: 131629 | D231: 1
A233: PREMIUM CATEGORY | B233: C
A235: PREMIUM % | B235: Sum of Unit Selling Area
A236: 0.275 | B236: 111
A237: A602 | B237: 111
A238: 0.32 | B238: 340
A239: B141 | B239: 170
A240: B244 | B240: 170
A241: 0.32 | B241: 340
A242: C141 | B242: 170
A243: C344 | B243: 170
A244: 0.325 | B244: 232
A245: B101 | B245: 116
A246: B204 | B246: 116
A247: 0.325 | B247: 448
A248: C101 | B248: 116
A249: C304 | B249: 116
A250: E101 | B250: 108
A251: E204 | B251: 108
A252: 0.33 | B252: 173
A253: C201 | B253: 173
...

Sheet GANNT CHART
A3: LAUNCH PHASE | V3: RH | AH3: CLOSING PHASE
B4: R1 | E4: R2 | H4: R3 | K4: R4 | N4: R5 | Q4: R6 | T4: R7 | W4: R8 | Z4: R9 | AC4: R10 | AF4: R11 | AI4: R12
C9: YEAR 2023 | G9: YEAR 2024 | S9: YEAR 2025 | AE9: YEAR 2026 | AQ9: YEAR 2027
C16: 1 | D16: 2 | E16: 3 | F16: 4
G18: 5 | H18: 6 | I18: 7 | J18: 8 | K18: 9 | L18: 10 | M18: 11 | N18: 12 | O18: 13 | P18: 14 | Q18: 15 | R18: 16 | S18: 17 | T18: 18 | U18: 19 | V18: 20 | W18: 21 | X18: 22
S20: 17 | T20: 18 | U20: 19 | V20: 20 | W20: 21 | X20: 22 | Y20: 23 | Z20: 24 | AA20: 25 | AB20: 26 | AC20: 27 | AD20: 28 | AE20: 29 | AF20: 30 | AG20: 31 | AH20: 32 | AI20: 33 | AJ20: 34
P21: 14 | Q21: 15 | R21: 16
AE22: 29 | AF22: 30 | AG22: 31 | AH22: 32 | AI22: 33 | AJ22: 34 | AK22: 35 | AL22: 36 | AM22: 37 | AN22: 38 | AO22: 39 | AP22: 40 | AQ22: 41 | AR22: 42 | AS22: 43 | AT22: 44 | AU22: 45 | AV22: 46
AB23: 26 | AC23: 27 | AD23: 28
AK24: 35 | AL24: 36 | AM24: 37 | AN24: 38 | AO24: 39 | AP24: 40 | AQ24: 41 | AR24: 42 | AS24: 43 | AT24: 44 | AU24: 45 | AV24: 46 | AW24: 47 | AX24: 48 | AY24: 49
AH25: 32 | AI25: 33 | AJ25: 34
A39: 45170 | H39: TENDERING & LICENSING | O39: CONSTRUCTION PHASE (C1) RESIDENTIAL | X39: CONSTRUCTION PHASE (C2) RESIDENTIAL | AG39: CONSTRUCTION PHASE (C3) RESIDENTIAL | AP39: CONSTRUCTION PHASE (C4) COMMERCIAL | AX39: 46631
O42: A1 | P42: A5 | Q42: B1 | R42: B5 | S42: B18 | X42: B6 | Y42: B10 | Z42: B14 | AA42: C4 | AG42: D1 | AH42: D5 | AI42: E4
O43: A2 | P43: A6 | Q43: B2 | R43: B15 | S43: B19 | X43: B7 | Y43: B11 | Z43: C1 | AA43: C5 | AG43: D2 | AH43: E1 | AI43: E5
O44: A3 | P44: A7 | Q44: B3 | R44: B16 | X44: B8 | Y44: B12 | Z44: C2 | AA44: C6 | AG44: D3 | AH44: E2
O45: A4 | P45: A8 | Q45: B4 | R45: B17 | X45: B9 | Y45: B13 | Z45: C3 | AG45: D4 | AH45: E3

Sheet DATA FOR PIVOT
A4: BLD Type | B4: ZONE | C4: BLD No. | D4: BLD. TYPE | E4: Floor | F4: UNIT | G4: Unit Number | H4: NO. OF BEDROOMS | I4: CONSTRUCTION PHASE | J4: Unit Net Area | K4: Unit Gross Area | L4: Unit Selling Area | M4: Private Garden Area | N4: No. of Bedrooms2 | O4: ORIENTATION | P4: INTERNAL LOCATION | Q4: VIEW | R4: FLOOR2 | S4: AREA CATEGORY | T4: P1 | U4: P2 | V4: P3 | W4: P4 | X4: P5 | Y4: TOTAL PREMIUM % | Z4: PREMIUM CATEGORY | AA4: SELLING PHASE NAME | AB4: PHASE (BUILDING) STARTING PRICE | AC4: PHASE (BUILDING) CLOSING PRICE | AD4: PHASE PREMIUM RANGE | AE4: UNIT PREMIUM VALUE | AF4: UNIT (BUILDING) RATE (SEMI FINISHED) | AG4: UNIT (GARDEN) RATE | AH4: UNIT (BUILDING) RATE (BASIC FINISH) | AI4: UNIT (BUILDING) RATE (FULLY FINISH) | AJ4: UNIT (BUILDING) VALUE SEMI FINISHED | AK4: UNIT (BUILDING) VALUE BASIC FINISHED | AL4: UNIT (BUILDING) VALUE FULLY FINISHED | AM4: UNIT (GARDEN) VALUE | AN4: MAINTENANCE VALUE | AO4: MAX. NO. OF CAR PARKING | AP4: PARKING VALUE | AQ4: TOTAL CARS VALUE | AR4: TOTAL UNIT VALUE (SEMI FINISHED) | AS4: TOTAL UNIT VALUE (BASIC FINISHED) | AT4: TOTAL UNIT VALUE (FULLY FINISHED) | AU4: UNIT DELIVERY DATE | AV4: PHASE SELLING START DATE
A5: A | B5: =LEFT(C5,1) -> A | C5: A1 | D5: RESIDENTIAL | E5: 0 | F5: 1 | G5: =LEFT(C5,2)&E5&F5 -> A101 | H5: 2 BEDROOM | I5: =VLOOKUP(C5,'PREMIUM TABLES'!$G$107:$H$149,2,FALSE) -> C1 | J5: 110.32 | K5: 120.40866 | L5: 136 | M5: 42.7795 | O5: SE | P5: CORNER | Q5: ROAD 18M (BUILDINGS) | R5: =VLOOKUP(E5,'PREMIUM TABLES'!$F$214:$G$219,2,FALSE) -> GROUND | S5: {=IF(AND(L5>0,L5<90),"A",IF(AND(L5>90,L5<123),"B",IF(AND(L5>122,L5<159),"C",IF(AND(L5>159,L5<185),"D",IF(AND(L5>185,L5<230),"E",IF(AND(L5>230,L5<350),"F",NONE))))))} -> C | T5: =VLOOKUP(O5,'PREMIUM TABLES'!$G$165:$H$172,2,FALSE) -> 0.08 | U5: =VLOOKUP(P5,'PREMIUM TABLES'!$G$208:$H$209,2,FALSE) -> 0.05 | V5: =VLOOKUP(Q5,'PREMIUM TABLES'!$G$175:$H$195,2,FALSE) -> 0.15 | W5: =VLOOKUP(R5,'PREMIUM TABLES'!$G$214:$H$219,2,FALSE) -> 0.05 | X5: =VLOOKUP(S5,'PREMIUM TABLES'!$F$199:$H$205,3,FALSE) -> 0.035 | Y5: =SUM(T5:X5) -> 0.365 | Z5: {=IF(AND(Y5>0,Y5<0.5),"C",IF(AND(Y5>=0.5,Y5<0.73),"B",IF(AND(Y5>=0.73,Y5<0.98),"A",NONE)))} -> C | AA5: =VLOOKUP(G5,'ALL (R)'!$N$5:$R$862,5,FALSE) -> R 2 | AB5: =VLOOKUP(AA5,FACTS!$B$2:$L$14,10,FALSE) -> 43562.5 | AC5: =VLOOKUP(AA5,FACTS!$B$2:$L$14,11,FALSE) -> 48687.5 | AD5: =VLOOKUP(AA5,FACTS!$B$2:$N$14,13,FALSE) -> 5125 | AE5: =AD5*Y5 -> 1870.625 | AF5: =AE5+AB5 -> 45433.125 | AG5: =AF5*FACTS!$T$2 -> 14992.931 | AH5: =Table1[[#This Row],[UNIT (BUILDING) RATE (SEMI FINISHED)]]+4500 -> 49933.125 | AI5: =Table1[[#This Row],[UNIT (BUILDING) RATE (SEMI FINISHED)]]+7500 -> 52933.125 | AJ5: =AF5*L5 -> 6178905 | AK5: =Table1[[#This Row],[UNIT (BUILDING) RATE (BASIC FINISH)]]*Table1[[#This Row],[Unit Selling Area]] -> 6790905 | AL5: =Table1[[#This Row],[UNIT (BUILDING) RATE (FULLY FINISH)]]*Table1[[#This Row],[Unit Selling Area]] -> 7198905 | AM5: =AG5*M5 -> 641390.1 | AN5: =(AM5+AJ5)*FACTS!$S$2 -> 579725.08 | AO5: =VLOOKUP(S5,FACTS!$A$17:$C$23,3,FALSE) -> 2 | AP5: =VLOOKUP(AA5,FACTS!$B$2:$J$14,9,FALSE) -> 205000 | AQ5: =Table1[[#This Row],[PARKING VALUE]]*1 -> 205000 | AR5: =AQ5+AM5+AJ5 -> 7025295.1 | AS5: =Table1[[#This Row],[TOTAL CARS VALUE]]+Table1[[#This Row],[UNIT (BUILDING) VALUE BASIC FINISHED]]+Table1[[#This Row],[UNIT (GARDEN) VALUE]] -> 7637295.1 | AT5: =Table1[[#This Row],[TOTAL CARS VALUE]]+Table1[[#This Row],[UNIT (GARDEN) VALUE]]+Table1[[#This Row],[UNIT (BUILDING) VALUE FULLY FINISHED]] -> 8045295.1 | AU5: =VLOOKUP(I5,'C PHASES'!$I$108:$J$110,2,FALSE) -> 45839 | AV5: =VLOOKUP(AA5,'C PHASES'!$I$113:$J$125,2,FALSE) -> 45292
B6: =LEFT(C6,1) -> A | C6: A1 | D6: RESIDENTIAL | E6: 0 | F6: 2 | G6: =LEFT(C6,2)&E6&F6 -> A102 | H6: 2 BEDROOM | I6: =VLOOKUP(C6,'PREMIUM TABLES'!$G$107:$H$149,2,FALSE) -> C1 | J6: 110.14 | K6: 120.2122 | L6: 135 | M6: 59.4821 | O6: NW | P6: CORNER | Q6: LAKE A-1 | R6: =VLOOKUP(E6,'PREMIUM TABLES'!$F$214:$G$219,2,FALSE) -> GROUND | S6: {=IF(AND(L6>0,L6<90),"A",IF(AND(L6>90,L6<123),"B",IF(AND(L6>122,L6<159),"C",IF(AND(L6>159,L6<185),"D",IF(AND(L6>185,L6<230),"E",IF(AND(L6>230,L6<350),"F",NONE))))))} -> C | T6: =VLOOKUP(O6,'PREMIUM TABLES'!$G$165:$H$172,2,FALSE) -> 0.13 | U6: =VLOOKUP(P6,'PREMIUM TABLES'!$G$208:$H$209,2,FALSE) -> 0.05 | V6: =VLOOKUP(Q6,'PREMIUM TABLES'!$G$175:$H$195,2,FALSE) -> 0.4 | W6: =VLOOKUP(R6,'PREMIUM TABLES'!$G$214:$H$219,2,FALSE) -> 0.05 | X6: =VLOOKUP(S6,'PREMIUM TABLES'!$F$199:$H$205,3,FALSE) -> 0.035 | Y6: =SUM(T6:X6) -> 0.665 | Z6: {=IF(AND(Y6>0,Y6<0.5),"C",IF(AND(Y6>=0.5,Y6<0.73),"B",IF(AND(Y6>=0.73,Y6<0.98),"A",NONE)))} -> B | AA6: =VLOOKUP(G6,'ALL (R)'!$N$5:$R$862,5,FALSE) -> R 6 | AB6: =VLOOKUP(AA6,FACTS!$B$2:$L$14,10,FALSE) -> 48450 | AC6: =VLOOKUP(AA6,FACTS!$B$2:$L$14,11,FALSE) -> 54150 | AD6: =VLOOKUP(AA6,FACTS!$B$2:$N$14,13,FALSE) -> 5700 | AE6: =AD6*Y6 -> 3790.5 | AF6: =AE6+AB6 -> 52240.5 | AG6: =AF6*FACTS!$T$2 -> 17239.365 | AH6: =Table1[[#This Row],[UNIT (BUILDING) RATE (SEMI FINISHED)]]+4500 -> 56740.5 | AI6: =Table1[[#This Row],[UNIT (BUILDING) RATE (SEMI FINISHED)]]+7500 -> 59740.5 | AJ6: =AF6*L6 -> 7052467.5 | AK6: =Table1[[#This Row],[UNIT (BUILDING) RATE (BASIC FINISH)]]*Table1[[#This Row],[Unit Selling Area]] -> 7659967.5 | AL6: =Table1[[#This Row],[UNIT (BUILDING) RATE (FULLY FINISH)]]*Table1[[#This Row],[Unit Selling Area]] -> 8064967.5 | AM6: =AG6*M6 -> 1025433.6 | AN6: =(AM6+AJ6)*FACTS!$S$2 -> 686621.6 | AO6: =VLOOKUP(S6,FACTS!$A$17:$C$23,3,FALSE) -> 2 | AP6: =VLOOKUP(AA6,FACTS!$B$2:$J$14,9,FALSE) -> 228000 | AQ6: =Table1[[#This Row],[PARKING VALUE]]*1 -> 228000 | AR6: =AQ6+AM6+AJ6 -> 8305901.1 | AS6: =Table1[[#This Row],[TOTAL CARS VALUE]]+Table1[[#This Row],[UNIT (BUILDING) VALUE BASIC FINISHED]]+Table1[[#This Row],[UNIT (GARDEN) VALUE]] -> 8913401.1 | AT6: =Table1[[#This Row],[TOTAL CARS VALUE]]+Table1[[#This Row],[UNIT (GARDEN) VALUE]]+Table1[[#This Row],[UNIT (BUILDING) VALUE FULLY FINISHED]] -> 9318401.1 | AU6: =VLOOKUP(I6,'C PHASES'!$I$108:$J$110,2,FALSE) -> 45839 | AV6: =VLOOKUP(AA6,'C PHASES'!$I$113:$J$125,2,FALSE) -> 45658
B7: =LEFT(C7,1) -> A | C7: A1 | D7: RESIDENTIAL | E7: 0 | F7: 3 | G7: =LEFT(C7,2)&E7&F7 -> A103 | H7: 2 BEDROOM | I7: =VLOOKUP(C7,'PREMIUM TABLES'!$G$107:$H$149,2,FALSE) -> C1 | J7: 89.96 | K7: 98.186758 | L7: 111 | M7: 50.5078 | O7: NW | P7: MIDDLE | Q7: LAKE A-1 | R7: =VLOOKUP(E7,'PREMIUM TABLES'!$F$214:$G$219,2,FALSE) -> GROUND | S7: {=IF(AND(L7>0,L7<90),"A",IF(AND(L7>90,L7<123),"B",IF(AND(L7>122,L7<159),"C",IF(AND(L7>159,L7<185),"D",IF(AND(L7>185,L7<230),"E",IF(AND(L7>230,L7<350),"F",NONE))))))} -> B | T7: =VLOOKUP(O7,'PREMIUM TABLES'!$G$165:$H$172,2,FALSE) -> 0.13 | U7: =VLOOKUP(P7,'PREMIUM TABLES'!$G$208:$H$209,2,FALSE) -> 0.025 | V7: =VLOOKUP(Q7,'PREMIUM TABLES'!$G$175:$H$195,2,FALSE) -> 0.4 | W7: =VLOOKUP(R7,'PREMIUM TABLES'!$G$214:$H$219,2,FALSE) -> 0.05 | X7: =VLOOKUP(S7,'PREMIUM TABLES'!$F$199:$H$205,3,FALSE) -> 0.04 | Y7: =SUM(T7:X7) -> 0.645 | Z7: {=IF(AND(Y7>0,Y7<0.5),"C",IF(AND(Y7>=0.5,Y7<0.73),"B",IF(AND(Y7>=0.73,Y7<0.98),"A",NONE)))} -> B | AA7: =VLOOKUP(G7,'ALL (R)'!$N$5:$R$862,5,FALSE) -> R 4 | AB7: =VLOOKUP(AA7,FACTS!$B$2:$L$14,10,FALSE) -> 45687.5 | AC7: =VLOOKUP(AA7,FACTS!$B$2:$L$14,11,FALSE) -> 51062.5 | AD7: =VLOOKUP(AA7,FACTS!$B$2:$N$14,13,FALSE) -> 5375 | AE7: =AD7*Y7 -> 3466.875 | AF7: =AE7+AB7 -> 49154.375 | AG7: =AF7*FACTS!$T$2 -> 16220.944 | AH7: =Table1[[#This Row],[UNIT (BUILDING) RATE (SEMI FINISHED)]]+4500 -> 53654.375 | AI7: =Table1[[#This Row],[UNIT (BUILDING) RATE (SEMI FINISHED)]]+7500 -> 56654.375 | AJ7: =AF7*L7 -> 5456135.6 | AK7: =Table1[[#This Row],[UNIT (BUILDING) RATE (BASIC FINISH)]]*Table1[[#This Row],[Unit Selling Area]] -> 5955635.6 | AL7: =Table1[[#This Row],[UNIT (BUILDING) RATE (FULLY FINISH)]]*Table1[[#This Row],[Unit Selling Area]] -> 6288635.6 | AM7: =AG7*M7 -> 819284.18 | AN7: =(AM7+AJ7)*FACTS!$S$2 -> 533410.68 | AO7: =VLOOKUP(S7,FACTS!$A$17:$C$23,3,FALSE) -> 1 | AP7: =VLOOKUP(AA7,FACTS!$B$2:$J$14,9,FALSE) -> 215000 | AQ7: =Table1[[#This Row],[PARKING VALUE]]*1 -> 215000 | AR7: =AQ7+AM7+AJ7 -> 6490419.8 | AS7: =Table1[[#This Row],[TOTAL CARS VALUE]]+Table1[[#This Row],[UNIT (BUILDING) VALUE BASIC FINISHED]]+Table1[[#This Row],[UNIT (GARDEN) VALUE]] -> 6989919.8 | AT7: =Table1[[#This Row],[TOTAL CARS VALUE]]+Table1[[#This Row],[UNIT (GARDEN) VALUE]]+Table1[[#This Row],[UNIT (BUILDING) VALUE FULLY FINISHED]] -> 7322919.8 | AU7: =VLOOKUP(I7,'C PHASES'!$I$108:$J$110,2,FALSE) -> 45839 | AV7: =VLOOKUP(AA7,'C PHASES'!$I$113:$J$125,2,FALSE) -> 45474
B8: =LEFT(C8,1) -> A | C8: A1 | D8: RESIDENTIAL | E8: 0 | F8: 4 | G8: =LEFT(C8,2)&E8&F8 -> A104 | H8: 1 BEDROOM (STUDIO) | I8: =VLOOKUP(C8,'PREMIUM TABLES'!$G$107:$H$149,2,FALSE) -> C1 | J8: 60.98 | K8: 66.556564 | L8: 75 | M8: 23.8084 | O8: SE | P8: MIDDLE | Q8: ROAD 18M (BUILDINGS) | R8: =VLOOKUP(E8,'PREMIUM TABLES'!$F$214:$G$219,2,FALSE) -> GROUND | S8: {=IF(AND(L8>0,L8<90),"A",IF(AND(L8>90,L8<123),"B",IF(AND(L8>122,L8<159),"C",IF(AND(L8>159,L8<185),"D",IF(AND(L8>185,L8<230),"E",IF(AND(L8>230,L8<350),"F",NONE))))))} -> A | T8: =VLOOKUP(O8,'PREMIUM TABLES'!$G$165:$H$172,2,FALSE) -> 0.08 | U8: =VLOOKUP(P8,'PREMIUM TABLES'!$G$208:$H$209,2,FALSE) -> 0.025 | V8: =VLOOKUP(Q8,'PREMIUM TABLES'!$G$175:$H$195,2,FALSE) -> 0.15 | W8: =VLOOKUP(R8,'PREMIUM TABLES'!$G$214:$H$219,2,FALSE) -> 0.05 | X8: =VLOOKUP(S8,'PREMIUM TABLES'!$F$199:$H$205,3,FALSE) -> 0.05 | Y8: =SUM(T8:X8) -> 0.355 | Z8: {=IF(AND(Y8>0,Y8<0.5),"C",IF(AND(Y8>=0.5,Y8<0.73),"B",IF(AND(Y8>=0.73,Y8<0.98),"A",NONE)))} -> C | AA8: =VLOOKUP(G8,'ALL (R)'!$N$5:$R$862,5,FALSE) -> R 1 | AB8: =VLOOKUP(AA8,FACTS!$B$2:$L$14,10,FALSE) -> 42500 | AC8: =VLOOKUP(AA8,FACTS!$B$2:$L$14,11,FALSE) -> 47500 | AD8: =VLOOKUP(AA8,FACTS!$B$2:$N$14,13,FALSE) -> 5000 | AE8: =AD8*Y8 -> 1775 | AF8: =AE8+AB8 -> 44275 | AG8: =AF8*FACTS!$T$2 -> 14610.75 | AH8: =Table1[[#This Row],[UNIT (BUILDING) RATE (SEMI FINISHED)]]+4500 -> 48775 | AI8: =Table1[[#This Row],[UNIT (BUILDING) RATE (SEMI FINISHED)]]+7500 -> 51775 | AJ8: =AF8*L8 -> 3320625 | AK8: =Table1[[#This Row],[UNIT (BUILDING) RATE (BASIC FINISH)]]*Table1[[#This Row],[Unit Selling Area]] -> 3658125 | AL8: =Table1[[#This Row],[UNIT (BUILDING) RATE (FULLY FINISH)]]*Table1[[#This Row],[Unit Selling Area]] -> 3883125 | AM8: =AG8*M8 -> 347858.58 | AN8: =(AM8+AJ8)*FACTS!$S$2 -> 311821.1 | AO8: =VLOOKUP(S8,FACTS!$A$17:$C$23,3,FALSE) -> 1 | AP8: =VLOOKUP(AA8,FACTS!$B$2:$J$14,9,FALSE) -> 200000 | AQ8: =Table1[[#This Row],[PARKING VALUE]]*1 -> 200000 | AR8: =AQ8+AM8+AJ8 -> 3868483.6 | AS8: =Table1[[#This Row],[TOTAL CARS VALUE]]+Table1[[#This Row],[UNIT (BUILDING) VALUE BASIC FINISHED]]+Table1[[#This Row],[UNIT (GARDEN) VALUE]] -> 4205983.6 | AT8: =Table1[[#This Row],[TOTAL CARS VALUE]]+Table1[[#This Row],[UNIT (GARDEN) VALUE]]+Table1[[#This Row],[UNIT (BUILDING) VALUE FULLY FINISHED]] -> 4430983.6 | AU8: =VLOOKUP(I8,'C PHASES'!$I$108:$J$110,2,FALSE) -> 45839 | AV8: =VLOOKUP(AA8,'C PHASES'!$I$113:$J$125,2,FALSE) -> 45170
B9: =LEFT(C9,1) -> A | C9: A1 | D9: RESIDENTIAL | E9: 1 | F9: 1 | G9: =LEFT(C9,2)&E9&F9 -> A111 | H9: 2 BEDROOM | I9: =VLOOKUP(C9,'PREMIUM TABLES'!$G$107:$H$149,2,FALSE) -> C1 | J9: 110.61 | K9: 120.72518 | L9: 136 | O9: SE | P9: CORNER | Q9: ROAD 18M (BUILDINGS) | R9: =VLOOKUP(E9,'PREMIUM TABLES'!$F$214:$G$219,2,FALSE) -> FIRST | S9: {=IF(AND(L9>0,L9<90),"A",IF(AND(L9>90,L9<123),"B",IF(AND(L9>122,L9<159),"C",IF(AND(L9>159,L9<185),"D",IF(AND(L9>185,L9<230),"E",IF(AND(L9>230,L9<350),"F",NONE))))))} -> C | T9: =VLOOKUP(O9,'PREMIUM TABLES'!$G$165:$H$172,2,FALSE) -> 0.08 | U9: =VLOOKUP(P9,'PREMIUM TABLES'!$G$208:$H$209,2,FALSE) -> 0.05 | V9: =VLOOKUP(Q9,'PREMIUM TABLES'!$G$175:$H$195,2,FALSE) -> 0.15 | W9: =VLOOKUP(R9,'PREMIUM TABLES'!$G$214:$H$219,2,FALSE) -> 0.07 | X9: =VLOOKUP(S9,'PREMIUM TABLES'!$F$199:$H$205,3,FALSE) -> 0.035 | Y9: =SUM(T9:X9) -> 0.385 | Z9: {=IF(AND(Y9>0,Y9<0.5),"C",IF(AND(Y9>=0.5,Y9<0.73),"B",IF(AND(Y9>=0.73,Y9<0.98),"A",NONE)))} -> C | AA9: =VLOOKUP(G9,'ALL (R)'!$N$5:$R$862,5,FALSE) -> R 4 | AB9: =VLOOKUP(AA9,FACTS!$B$2:$L$14,10,FALSE) -> 45687.5 | AC9: =VLOOKUP(AA9,FACTS!$B$2:$L$14,11,FALSE) -> 51062.5 | AD9: =VLOOKUP(AA9,FACTS!$B$2:$N$14,13,FALSE) -> 5375 | AE9: =AD9*Y9 -> 2069.375 | AF9: =AE9+AB9 -> 47756.875 | AG9: =AF9*FACTS!$T$2 -> 15759.769 | AH9: =Table1[[#This Row],[UNIT (BUILDING) RATE (SEMI FINISHED)]]+4500 -> 52256.875 | AI9: =Table1[[#This Row],[UNIT (BUILDING) RATE (SEMI FINISHED)]]+7500 -> 55256.875 | AJ9: =AF9*L9 -> 6494935 | AK9: =Table1[[#This Row],[UNIT (BUILDING) RATE (BASIC FINISH)]]*Table1[[#This Row],[Unit Selling Area]] -> 7106935 | AL9: =Table1[[#This Row],[UNIT (BUILDING) RATE (FULLY FINISH)]]*Table1[[#This Row],[Unit Selling Area]] -> 7514935 | AM9: =AG9*M9 -> 0 | AN9: =(AM9+AJ9)*FACTS!$S$2 -> 552069.48 | AO9: =VLOOKUP(S9,FACTS!$A$17:$C$23,3,FALSE) -> 2 | AP9: =VLOOKUP(AA9,FACTS!$B$2:$J$14,9,FALSE) -> 215000 | AQ9: =Table1[[#This Row],[PARKING VALUE]]*1 -> 215000 | AR9: =AQ9+AM9+AJ9 -> 6709935 | AS9: =Table1[[#This Row],[TOTAL CARS VALUE]]+Table1[[#This Row],[UNIT (BUILDING) VALUE BASIC FINISHED]]+Table1[[#This Row],[UNIT (GARDEN) VALUE]] -> 7321935 | AT9: =Table1[[#This Row],[TOTAL CARS VALUE]]+Table1[[#This Row],[UNIT (GARDEN) VALUE]]+Table1[[#This Row],[UNIT (BUILDING) VALUE FULLY FINISHED]] -> 7729935 | AU9: =VLOOKUP(I9,'C PHASES'!$I$108:$J$110,2,FALSE) -> 45839 | AV9: =VLOOKUP(AA9,'C PHASES'!$I$113:$J$125,2,FALSE) -> 45474
B10: =LEFT(C10,1) -> A | C10: A1 | D10: RESIDENTIAL | E10: 1 | F10: 2 | G10: =LEFT(C10,2)&E10&F10 -> A112 | H10: 2 BEDROOM | I10: =VLOOKUP(C10,'PREMIUM TABLES'!$G$107:$H$149,2,FALSE) -> C1 | J10: 110.14 | K10: 120.2122 | L10: 135 | O10: NW | P10: CORNER | Q10: LAKE A-1 | R10: =VLOOKUP(E10,'PREMIUM TABLES'!$F$214:$G$219,2,FALSE) -> FIRST | S10: {=IF(AND(L10>0,L10<90),"A",IF(AND(L10>90,L10<123),"B",IF(AND(L10>122,L10<159),"C",IF(AND(L10>159,L10<185),"D",IF(AND(L10>185,L10<230),"E",IF(AND(L10>230,L10<350),"F",NONE))))))} -> C | T10: =VLOOKUP(O10,'PREMIUM TABLES'!$G$165:$H$172,2,FALSE) -> 0.13 | U10: =VLOOKUP(P10,'PREMIUM TABLES'!$G$208:$H$209,2,FALSE) -> 0.05 | V10: =VLOOKUP(Q10,'PREMIUM TABLES'!$G$175:$H$195,2,FALSE) -> 0.4 | W10: =VLOOKUP(R10,'PREMIUM TABLES'!$G$214:$H$219,2,FALSE) -> 0.07 | X10: =VLOOKUP(S10,'PREMIUM TABLES'!$F$199:$H$205,3,FALSE) -> 0.035 | Y10: =SUM(T10:X10) -> 0.685 | Z10: {=IF(AND(Y10>0,Y10<0.5),"C",IF(AND(Y10>=0.5,Y10<0.73),"B",IF(AND(Y10>=0.73,Y10<0.98),"A",NONE)))} -> B | AA10: =VLOOKUP(G10,'ALL (R)'!$N$5:$R$862,5,FALSE) -> R 8 | AB10: =VLOOKUP(AA10,FACTS!$B$2:$L$14,10,FALSE) -> 51850 | AC10: =VLOOKUP(AA10,FACTS!$B$2:$L$14,11,FALSE) -> 57950 | AD10: =VLOOKUP(AA10,FACTS!$B$2:$N$14,13,FALSE) -> 6100 | AE10: =AD10*Y10 -> 4178.5 | AF10: =AE10+AB10 -> 56028.5 | AG10: =AF10*FACTS!$T$2 -> 18489.405 | AH10: =Table1[[#This Row],[UNIT (BUILDING) RATE (SEMI FINISHED)]]+4500 -> 60528.5 | AI10: =Table1[[#This Row],[UNIT (BUILDING) RATE (SEMI FINISHED)]]+7500 -> 63528.5 | AJ10: =AF10*L10 -> 7563847.5 | AK10: =Table1[[#This Row],[UNIT (BUILDING) RATE (BASIC FINISH)]]*Table1[[#This Row],[Unit Selling Area]] -> 8171347.5 | AL10: =Table1[[#This Row],[UNIT (BUILDING) RATE (FULLY FINISH)]]*Table1[[#This Row],[Unit Selling Area]] -> 8576347.5 | AM10: =AG10*M10 -> 0 | AN10: =(AM10+AJ10)*FACTS!$S$2 -> 642927.04 | AO10: =VLOOKUP(S10,FACTS!$A$17:$C$23,3,FALSE) -> 2 | AP10: =VLOOKUP(AA10,FACTS!$B$2:$J$14,9,FALSE) -> 244000 | AQ10: =Table1[[#This Row],[PARKING VALUE]]*1 -> 244000 | AR10: =AQ10+AM10+AJ10 -> 7807847.5 | AS10: =Table1[[#This Row],[TOTAL CARS VALUE]]+Table1[[#This Row],[UNIT (BUILDING) VALUE BASIC FINISHED]]+Table1[[#This Row],[UNIT (GARDEN) VALUE]] -> 8415347.5 | AT10: =Table1[[#This Row],[TOTAL CARS VALUE]]+Table1[[#This Row],[UNIT (GARDEN) VALUE]]+Table1[[#This Row],[UNIT (BUILDING) VALUE FULLY FINISHED]] -> 8820347.5 | AU10: =VLOOKUP(I10,'C PHASES'!$I$108:$J$110,2,FALSE) -> 45839 | AV10: =VLOOKUP(AA10,'C PHASES'!$I$113:$J$125,2,FALSE) -> 45839
B11: =LEFT(C11,1) -> A | C11: A1 | D11: RESIDENTIAL | E11: 1 | F11: 3 | G11: =LEFT(C11,2)&E11&F11 -> A113 | H11: 2 BEDROOM | I11: =VLOOKUP(C11,'PREMIUM TABLES'!$G$107:$H$149,2,FALSE) -> C1 | J11: 89.05 | K11: 97.193539 | L11: 110 | O11: NW | P11: MIDDLE | Q11: LAKE A-1 | R11: =VLOOKUP(E11,'PREMIUM TABLES'!$F$214:$G$219,2,FALSE) -> FIRST | S11: {=IF(AND(L11>0,L11<90),"A",IF(AND(L11>90,L11<123),"B",IF(AND(L11>122,L11<159),"C",IF(AND(L11>159,L11<185),"D",IF(AND(L11>185,L11<230),"E",IF(AND(L11>230,L11<350),"F",NONE))))))} -> B | T11: =VLOOKUP(O11,'PREMIUM TABLES'!$G$165:$H$172,2,FALSE) -> 0.13 | U11: =VLOOKUP(P11,'PREMIUM TABLES'!$G$208:$H$209,2,FALSE) -> 0.025 | V11: =VLOOKUP(Q11,'PREMIUM TABLES'!$G$175:$H$195,2,FALSE) -> 0.4 | W11: =VLOOKUP(R11,'PREMIUM TABLES'!$G$214:$H$219,2,FALSE) -> 0.07 | X11: =VLOOKUP(S11,'PREMIUM TABLES'!$F$199:$H$205,3,FALSE) -> 0.04 | Y11: =SUM(T11:X11) -> 0.665 | Z11: {=IF(AND(Y11>0,Y11<0.5),"C",IF(AND(Y11>=0.5,Y11<0.73),"B",IF(AND(Y11>=0.73,Y11<0.98),"A",NONE)))} -> B | AA11: =VLOOKUP(G11,'ALL (R)'!$N$5:$R$862,5,FALSE) -> R 5 | AB11: =VLOOKUP(AA11,FACTS!$B$2:$L$14,10,FALSE) -> 46750 | AC11: =VLOOKUP(AA11,FACTS!$B$2:$L$14,11,FALSE) -> 52250 | AD11: =VLOOKUP(AA11,FACTS!$B$2:$N$14,13,FALSE) -> 5500 | AE11: =AD11*Y11 -> 3657.5 | AF11: =AE11+AB11 -> 50407.5 | AG11: =AF11*FACTS!$T$2 -> 16634.475 | AH11: =Table1[[#This Row],[UNIT (BUILDING) RATE (SEMI FINISHED)]]+4500 -> 54907.5 | AI11: =Table1[[#This Row],[UNIT (BUILDING) RATE (SEMI FINISHED)]]+7500 -> 57907.5 | AJ11: =AF11*L11 -> 5544825 | AK11: =Table1[[#This Row],[UNIT (BUILDING) RATE (BASIC FINISH)]]*Table1[[#This Row],[Unit Selling Area]] -> 6039825 | AL11: =Table1[[#This Row],[UNIT (BUILDING) RATE (FULLY FINISH)]]*Table1[[#This Row],[Unit Selling Area]] -> 6369825 | AM11: =AG11*M11 -> 0 | AN11: =(AM11+AJ11)*FACTS!$S$2 -> 471310.13 | AO11: =VLOOKUP(S11,FACTS!$A$17:$C$23,3,FALSE) -> 1 | AP11: =VLOOKUP(AA11,FACTS!$B$2:$J$14,9,FALSE) -> 220000 | AQ11: =Table1[[#This Row],[PARKING VALUE]]*1 -> 220000 | AR11: =AQ11+AM11+AJ11 -> 5764825 | AS11: =Table1[[#This Row],[TOTAL CARS VALUE]]+Table1[[#This Row],[UNIT (BUILDING) VALUE BASIC FINISHED]]+Table1[[#This Row],[UNIT (GARDEN) VALUE]] -> 6259825 | AT11: =Table1[[#This Row],[TOTAL CARS VALUE]]+Table1[[#This Row],[UNIT (GARDEN) VALUE]]+Table1[[#This Row],[UNIT (BUILDING) VALUE FULLY FINISHED]] -> 6589825 | AU11: =VLOOKUP(I11,'C PHASES'!$I$108:$J$110,2,FALSE) -> 45839 | AV11: =VLOOKUP(AA11,'C PHASES'!$I$113:$J$125,2,FALSE) -> 45566
